<?xml version="1.0"?>
<sdf version="1.6">
        <physics name="default_physics" type="ode">
            <max_step_size>0.001
            </max_step_size>
            <real_time_factor>1
            </real_time_factor>
            <real_time_update_rate>1000
            </real_time_update_rate>
            <ode>
                <solver>
                    <type>quick
                    </type>
                    <iters>100
                    </iters>
                    <sor>1.3
                    </sor>
                </solver>
                <constraints>
                    <cfm>0
                    </cfm>
                    <erp>0.2
                    </erp>
                    <contact_max_correcting_vel>100
                    </contact_max_correcting_vel>
                    <contact_surface_layer>0.001
                    </contact_surface_layer>
                </constraints>
                <gravity>0 0 -9.81
                </gravity>
                <magnetic_field>4.892e-05 1.378e-05 -4.916e-05
                </magnetic_field>
            </ode>
        </physics>
    <model name="X4">
        <link name="base_link">
            <inertial>
                <mass>3.42
                </mass>
                <inertia>
                    <ixx>0.075
                    </ixx>
                    <ixy>0
                    </ixy>
                    <ixz>0
                    </ixz>
                    <iyy>0.075
                    </iyy>
                    <iyz>0
                    </iyz>
                    <izz>0.148916
                    </izz>
                </inertia>
            </inertial>
            <collision name="base_link_inertia_collision">
                <geometry>
                    <box>
                        <size>0.3 0.3 0.25
                        </size>
                    </box>
                </geometry>
            </collision>
            <visual name="base_link_inertia_visual">
                <geometry>
                    <mesh>
                        <scale>1 1 1
                        </scale>
                        <uri>model:://X4_GPS_LIDAR_RGBD/meshes/x4.dae
                        </uri>
                    </mesh>
                </geometry>
            </visual>
            <visual name="marker_visual_1">
                <geometry>
                    <mesh>
                        <scale>1 1 1
                        </scale>
                        <uri>model:://X4_GPS_LIDAR_RGBD/meshes/led.dae
                        </uri>
                    </mesh>
                </geometry>
            </visual>
            <visual name="marker_visual_2">
                <geometry>
                    <mesh>
                        <scale>1 1 1
                        </scale>
                        <uri>model:://X4_GPS_LIDAR_RGBD/meshes/led.dae
                        </uri>
                    </mesh>
                </geometry>
            </visual>
            <visual name="marker_visual_3">          
                <geometry>
                    <mesh>
                        <scale>1 1 1
                        </scale>
                        <uri>model:://X4_GPS_LIDAR_RGBD/meshes/led.dae
                        </uri>
                    </mesh>
                </geometry>
            </visual>
            <visual name="downward_flashlight_visual">
                <geometry>
                    <mesh>
                        <scale>0.01 0.01 0.01
                        </scale>
                        <uri>model:://X4_GPS_LIDAR_RGBD/meshes/spotlight.dae
                        </uri>
                    </mesh>
                </geometry>
            </visual>
            <visual name="left_flashlight_visual">
                <geometry>
                    <mesh>
                        <scale>0.01 0.01 0.01
                        </scale>
                        <uri>model:://X4_GPS_LIDAR_RGBD/meshes/spotlight.dae
                        </uri>
                    </mesh>
                </geometry>
            </visual>
            <visual name="right_flashlight_visual">
                <geometry>
                    <mesh>
                        <scale>0.01 0.01 0.01
                        </scale>
                        <uri>model:://X4_GPS_LIDAR_RGBD/meshes/spotlight.dae
                        </uri>
                    </mesh>
                </geometry>
            </visual>
            
            <!-- ====================== -->
            <!-- ADDED SENSORS & PLUGINS -->
            <!-- ====================== -->
            
            <!-- IMU Sensor with Plugin -->
            <sensor name="imu_sensor" type="imu">
                <always_on>1</always_on>
                <update_rate>250</update_rate>
                <imu>
                    <enable_orientation>0</enable_orientation>
                    <angular_velocity>
                        <x>
                            <noise type="gaussian">
                                <mean>0</mean>
                                <stddev>0.009</stddev>
                                <bias_mean>0.00075</bias_mean>
                                <bias_stddev>0.005</bias_stddev>
                                <dynamic_bias_stddev>0.00002</dynamic_bias_stddev>
                                <dynamic_bias_correlation_time>400.0</dynamic_bias_correlation_time>
                                <precision>0.00025</precision>
                            </noise>
                        </x>
                        <y>
                            <noise type="gaussian">
                                <mean>0</mean>
                                <stddev>0.009</stddev>
                                <bias_mean>0.00075</bias_mean>
                                <bias_stddev>0.005</bias_stddev>
                                <dynamic_bias_stddev>0.00002</dynamic_bias_stddev>
                                <dynamic_bias_correlation_time>400.0</dynamic_bias_correlation_time>
                                <precision>0.00025</precision>
                            </noise>
                        </y>
                        <z>
                            <noise type="gaussian">
                                <mean>0</mean>
                                <stddev>0.009</stddev>
                                <bias_mean>0.00075</bias_mean>
                                <bias_stddev>0.005</bias_stddev>
                                <dynamic_bias_stddev>0.00002</dynamic_bias_stddev>
                                <dynamic_bias_correlation_time>400.0</dynamic_bias_correlation_time>
                                <precision>0.00025</precision>
                            </noise>
                        </z>
                    </angular_velocity>
                    <linear_acceleration>
                        <x>
                            <noise type="gaussian">
                                <mean>0</mean>
                                <stddev>0.021</stddev>
                                <bias_mean>0.05</bias_mean>
                                <bias_stddev>0.0075</bias_stddev>
                                <dynamic_bias_stddev>0.000375</dynamic_bias_stddev>
                                <dynamic_bias_correlation_time>175.0</dynamic_bias_correlation_time>
                                <precision>0.005</precision>
                            </noise>
                        </x>
                        <y>
                            <noise type="gaussian">
                                <mean>0</mean>
                                <stddev>0.021</stddev>
                                <bias_mean>0.05</bias_mean>
                                <bias_stddev>0.0075</bias_stddev>
                                <dynamic_bias_stddev>0.000375</dynamic_bias_stddev>
                                <dynamic_bias_correlation_time>175.0</dynamic_bias_correlation_time>
                                <precision>0.005</precision>
                            </noise>
                        </y>
                        <z>
                            <noise type="gaussian">
                                <mean>0</mean>
                                <stddev>0.021</stddev>
                                <bias_mean>0.05</bias_mean>
                                <bias_stddev>0.0075</bias_stddev>
                                <dynamic_bias_stddev>0.000375</dynamic_bias_stddev>
                                <dynamic_bias_correlation_time>175.0</dynamic_bias_correlation_time>
                                <precision>0.005</precision>
                            </noise>
                        </z>
                    </linear_acceleration>
                </imu>
                <plugin filename="libgazebo_ros_imu_sensor.so" name="imu_plugin">
                    <ros>
                        <namespace>/X4</namespace>
                    </ros>
                    <topic_name>imu</topic_name>
                    <bodyName>base_link</bodyName>
                    <updateRate>250</updateRate>
                    <gaussianNoise>0.0</gaussianNoise>
                    <alwaysOn>true</alwaysOn>
                </plugin>
            </sensor>
            
            <!-- LIDAR Sensor with Plugin -->
            <sensor name="scan_omni" type="gpu_lidar">
                <pose>-0.1855 0 0.5318 0 0 0</pose>
                <update_rate>10</update_rate>
                <lidar>
                    <scan>
                        <horizontal>
                            <samples>1800</samples>
                            <resolution>1</resolution>
                            <min_angle>-3.141592654</min_angle>
                            <max_angle>3.141592654</max_angle>
                        </horizontal>
                        <vertical>
                            <samples>16</samples>
                            <resolution>1</resolution>
                            <min_angle>-0.261799388</min_angle>
                            <max_angle>0.261799388</max_angle>
                        </vertical>
                    </scan>
                    <range>
                        <min>0.2</min>
                        <max>100.0</max>
                        <resolution>0.01</resolution>
                    </range>
                    <noise>
                        <type>gaussian</type>
                        <mean>0</mean>
                        <stddev>0.01</stddev>
                    </noise>
                </lidar>
                <always_on>false</always_on>
                <visualize>false</visualize>
                <plugin filename="libgazebo_ros_ray_sensor.so" name="lidar_plugin">
                    <ros>
                        <namespace>/X4</namespace>
                        <remapping>~/out:=scan</remapping>
                    </ros>
                    <topicName>scan</topicName>
                    <frameName>base_link</frameName>
                    <alwaysOn>false</alwaysOn>
                    <updateRate>10</updateRate>
                </plugin>
            </sensor>
            
            <!-- RGBD Camera Sensor with Plugin -->
            <sensor name="camera_front" type="rgbd_camera">
                <pose>0.2 0 0 0 0.785 0</pose>
                <always_on>1</always_on>
                <update_rate>20</update_rate>
                <camera name="camera_front">
                    <horizontal_fov>1.0472</horizontal_fov>
                    <lens>
                        <intrinsics>
                            <fx>277.1</fx>
                            <fy>277.1</fy>
                            <cx>160.5</cx>
                            <cy>120.5</cy>
                            <s>0</s>
                        </intrinsics>
                    </lens>
                    <distortion>
                        <k1>0.0</k1>
                        <k2>0.0</k2>
                        <k3>0.0</k3>
                        <p1>0.0</p1>
                        <p2>0.0</p2>
                        <center>0.5 0.5</center>
                    </distortion>
                    <image>
                        <width>320</width>
                        <height>240</height>
                        <format>R8G8B8</format>
                    </image>
                    <clip>
                        <near>0.01</near>
                        <far>300</far>
                    </clip>
                    <depth_camera>
                        <clip>
                            <near>0.1</near>
                            <far>10</far>
                        </clip>
                    </depth_camera>
                    <noise>
                        <type>gaussian</type>
                        <mean>0</mean>
                        <stddev>0.007</stddev>
                    </noise>
                </camera>
                <plugin filename="libgazebo_ros_camera.so" name="camera_plugin">
                    <ros>
                        <namespace>/X4</namespace>
                    </ros>
                    <cameraName>camera_front</cameraName>
                    <imageTopicName>image_raw</imageTopicName>
                    <cameraInfoTopicName>camera_info</cameraInfoTopicName>
                    <frameName>camera_front</frameName>
                    <alwaysOn>true</alwaysOn>
                    <updateRate>20</updateRate>
                    <hfov>1.0472</hfov>
                </plugin>
                <plugin filename="libgazebo_ros_depth_camera.so" name="depth_camera_plugin">
                    <ros>
                        <namespace>/X4</namespace>
                    </ros>
                    <depthImageTopicName>depth/image_raw</depthImageTopicName>
                    <depthImageCameraInfoTopicName>depth/camera_info</depthImageCameraInfoTopicName>
                    <pointCloudTopicName>points</pointCloudTopicName>
                    <frameName>camera_front</frameName>
                    <alwaysOn>true</alwaysOn>
                    <updateRate>20</updateRate>
                    <hfov>1.0472</hfov>
                </plugin>
            </sensor>
            
            <!-- Thermal Camera (New Addition) -->
            <visual name="thermal_camera_visual">
                <pose>0.12 0 -0.08 0 0 0</pose>
                <geometry>
                    <box>
                        <size>0.02 0.025 0.025</size>
                    </box>
                </geometry>
            </visual>
            
            <sensor name="thermal_camera" type="camera">
                <pose>0.12 0 -0.08 0 0 0</pose>
                <camera name="thermal_camera">
                    <horizontal_fov>1.0472</horizontal_fov>
                    <image>
                        <width>320</width>
                        <height>240</height>
                        <format>L8</format>
                    </image>
                    <clip>
                        <near>0.1</near>
                        <far>100</far>
                    </clip>
                    <noise>
                        <type>gaussian</type>
                        <mean>0</mean>
                        <stddev>0.007</stddev>
                    </noise>
                    <thermal>
                        <min_temp>253.15</min_temp>  <!-- -20°C -->
                        <max_temp>313.15</max_temp>  <!-- 40°C -->
                        <resolution>0.1</resolution>
                    </thermal>
                </camera>
                <always_on>true</always_on>
                <update_rate>10</update_rate>
                <plugin filename="libgazebo_ros_thermal_camera.so" name="thermal_camera_plugin">
                    <ros>
                        <namespace>/X4</namespace>
                    </ros>
                    <cameraName>thermal_camera</cameraName>
                    <imageTopicName>thermal_image</imageTopicName>
                    <cameraInfoTopicName>thermal_camera_info</cameraInfoTopicName>
                    <frameName>thermal_camera</frameName>
                    <alwaysOn>true</alwaysOn>
                    <updateRate>10</updateRate>
                </plugin>
            </sensor>
            
            <visual name="camera_mount_base_visual">
                <geometry>
                    <box>
                        <size>0.06 0.06 0.006
                        </size>
                    </box>
                </geometry>
            </visual>
            <visual name="camera_mount_arm_visual">
                <geometry>
                    <cylinder>
                        <radius>0.005
                        </radius>
                        <length>0.08
                        </length>
                    </cylinder>
                </geometry>
            </visual>
            <visual name="camera_mount_arm2_visual">
                <geometry>
                    <cylinder>
                        <radius>0.01
                        </radius>
                        <length>0.025
                        </length>
                    </cylinder>
                </geometry>
            </visual>
            <visual name="camera_visual">
                <geometry>
                    <box>
                        <size>0.02 0.025 0.025
                        </size>
                    </box>
                </geometry>
            </visual>
        </link>
        <link name="rotor_0">
            <inertial>
                <mass>0.005
                </mass>
                <inertia>
                    <ixx>9.75e-07
                    </ixx>
                    <ixy>0
                    </ixy>
                    <ixz>0
                    </ixz>
                    <iyy>8.13545e-05
                    </iyy>
                    <iyz>0
                    </iyz>
                    <izz>8.22545e-05
                    </izz>
                </inertia>
            </inertial>
            <collision name="rotor_0_collision">
                <geometry>
                    <cylinder>
                        <length>0.005
                        </length>
                        <radius>0.1397
                        </radius>
                    </cylinder>
                </geometry>
                <surface>
                    <contact>
                        <ode/>
                    </contact>
                    <friction>
                        <ode/>
                    </friction>
                </surface>
            </collision>
            <visual name="rotor_0_visual">
                <geometry>
                    <mesh>
                        <scale>1 1 1
                        </scale>
                        <uri>model:://X4_GPS_LIDAR_RGBD/meshes/neo11_propeller_ccw.dae
                        </uri>
                    </mesh>
                </geometry>
                <cast_shadows>0
                </cast_shadows>
            </visual>
            <gravity>1
            </gravity>
            <velocity_decay/>
        </link>
        <joint name="rotor_0_joint" type="revolute">
            <child>rotor_0
            </child>
            <parent>base_link
            </parent>
            <axis>
                <xyz>0.043578 -0.075479 0.996195
                </xyz>
                <limit>
                    <lower>-1e+16
                    </lower>
                    <upper>1e+16
                    </upper>
                </limit>
                <dynamics>
                    <spring_reference>0
                    </spring_reference>
                    <spring_stiffness>0
                    </spring_stiffness>
                </dynamics>
                <use_parent_model_frame>1
                </use_parent_model_frame>
            </axis>
        </joint>
        <link name="rotor_1">
            <inertial>
                <mass>0.005
                </mass>
                <inertia>
                    <ixx>9.75e-07
                    </ixx>
                    <ixy>0
                    </ixy>
                    <ixz>0
                    </ixz>
                    <iyy>8.13545e-05
                    </iyy>
                    <iyz>0
                    </iyz>
                    <izz>8.22545e-05
                    </izz>
                </inertia>
            </inertial>
            <collision name="rotor_1_collision">
                <geometry>
                    <cylinder>
                        <length>0.005
                        </length>
                        <radius>0.1397
                        </radius>
                    </cylinder>
                </geometry>
                <surface>
                    <contact>
                        <ode/>
                    </contact>
                    <friction>
                        <ode/>
                    </friction>
                </surface>
            </collision>
            <visual name="rotor_1_visual">
                <geometry>
                    <mesh>
                        <scale>1 1 1
                        </scale>
                        <uri>model:://X4_GPS_LIDAR_RGBD/meshes/neo11_propeller_cw.dae
                        </uri>
                    </mesh>
                </geometry>
                <cast_shadows>0
                </cast_shadows>
            </visual>
            <gravity>1
            </gravity>
            <velocity_decay/>
        </link>
        <joint name="rotor_1_joint" type="revolute">
            <child>rotor_1
            </child>
            <parent>base_link
            </parent>
            <axis>
                <xyz>-0.087156 0 0.996195
                </xyz>
                <limit>
                    <lower>-1e+16
                    </lower>
                    <upper>1e+16
                    </upper>
                </limit>
                <dynamics>
                    <spring_reference>0
                    </spring_reference>
                    <spring_stiffness>0
                    </spring_stiffness>
                </dynamics>
                <use_parent_model_frame>1
                </use_parent_model_frame>
            </axis>
        </joint>
        <link name="rotor_2">
            <inertial>
                <mass>0.005
                </mass>
                <inertia>
                    <ixx>9.75e-07
                    </ixx>
                    <ixy>0
                    </ixy>
                    <ixz>0
                    </ixz>
                    <iyy>8.13545e-05
                    </iyy>
                    <iyz>0
                    </iyz>
                    <izz>8.22545e-05
                    </izz>
                </inertia>
            </inertial>
            <collision name="rotor_2_collision">
                <geometry>
                    <cylinder>
                        <length>0.005
                        </length>
                        <radius>0.1397
                        </radius>
                    </cylinder>
                </geometry>
                <surface>
                    <contact>
                        <ode/>
                    </contact>
                    <friction>
                        <ode/>
                    </friction>
                </surface>
            </collision>
            <visual name="rotor_2_visual">
                <geometry>
                    <mesh>
                        <scale>1 1 1
                        </scale>
                        <uri>model:://X4_GPS_LIDAR_RGBD/meshes/neo11_propeller_ccw.dae
                        </uri>
                    </mesh>
                </geometry>
                <cast_shadows>0
                </cast_shadows>
            </visual>
            <gravity>1
            </gravity>
            <velocity_decay/>
        </link>
        <joint name="rotor_2_joint" type="revolute">
            <child>rotor_2
            </child>
            <parent>base_link
            </parent>
            <axis>
                <xyz>0.043578 0.075479 0.996195
                </xyz>
                <limit>
                    <lower>-1e+16
                    </lower>
                    <upper>1e+16
                    </upper>
                </limit>
                <dynamics>
                    <spring_reference>0
                    </spring_reference>
                    <spring_stiffness>0
                    </spring_stiffness>
                </dynamics>
                <use_parent_model_frame>1
                </use_parent_model_frame>
            </axis>
        </joint>
        <link name="rotor_3">
            <inertial>
                <mass>0.005
                </mass>
                <inertia>
                    <ixx>9.75e-07
                    </ixx>
                    <ixy>0
                    </ixy>
                    <ixz>0
                    </ixz>
                    <iyy>8.13545e-05
                    </iyy>
                    <iyz>0
                    </iyz>
                    <izz>8.22545e-05
                    </izz>
                </inertia>
            </inertial>
            <collision name="rotor_3_collision">
                <geometry>
                    <cylinder>
                        <length>0.005
                        </length>
                        <radius>0.1397
                        </radius>
                    </cylinder>
                </geometry>
                <surface>
                    <contact>
                        <ode/>
                    </contact>
                    <friction>
                        <ode/>
                    </friction>
                </surface>
            </collision>
            <visual name="rotor_3_visual">
                <geometry>
                    <mesh>
                        <scale>1 1 1
                        </scale>
                        <uri>model:://X4_GPS_LIDAR_RGBD/meshes/neo11_propeller_cw.dae
                        </uri>
                    </mesh>
                </geometry>
                <cast_shadows>0
                </cast_shadows>
            </visual>
            <gravity>1
            </gravity>
            <velocity_decay/>
        </link>
        <joint name="rotor_3_joint" type="revolute">
            <child>rotor_3
            </child>
            <parent>base_link
            </parent>
            <axis>
                <xyz>0.043578 -0.075479 0.996195
                </xyz>
                <limit>
                    <lower>-1e+16
                    </lower>
                    <upper>1e+16
                    </upper>
                </limit>
                <dynamics>
                    <spring_reference>0
                    </spring_reference>
                    <spring_stiffness>0
                    </spring_stiffness>
                </dynamics>
                <use_parent_model_frame>1
                </use_parent_model_frame>
            </axis>
        </joint>
        <link name="rotor_4">
            <inertial>
                <mass>0.005
                </mass>
                <inertia>
                    <ixx>9.75e-07
                    </ixx>
                    <ixy>0
                    </ixy>
                    <ixz>0
                    </ixz>
                    <iyy>8.13545e-05
                    </iyy>
                    <iyz>0
                    </iyz>
                    <izz>8.22545e-05
                    </izz>
                </inertia>
            </inertial>
            <collision name="rotor_4_collision">
                <geometry>
                    <cylinder>
                        <length>0.005
                        </length>
                        <radius>0.1397
                        </radius>
                    </cylinder>
                </geometry>
                <surface>
                    <contact>
                        <ode/>
                    </contact>
                    <friction>
                        <ode/>
                    </friction>
                </surface>
            </collision>
            <visual name="rotor_4_visual">
                <geometry>
                    <mesh>
                        <scale>1 1 1
                        </scale>
                        <uri>model:://X4_GPS_LIDAR_RGBD/meshes/neo11_propeller_ccw.dae
                        </uri>
                    </mesh>
                </geometry>
                <cast_shadows>0
                </cast_shadows>
            </visual>
            <gravity>1
            </gravity>
            <velocity_decay/>
        </link>
        <joint name="rotor_4_joint" type="revolute">
            <child>rotor_4
            </child>
            <parent>base_link
            </parent>
            <axis>
                <xyz>-0.087156 -0 0.996195
                </xyz>
                <limit>
                    <lower>-1e+16
                    </lower>
                    <upper>1e+16
                    </upper>
                </limit>
                <dynamics>
                    <spring_reference>0
                    </spring_reference>
                    <spring_stiffness>0
                    </spring_stiffness>
                </dynamics>
                <use_parent_model_frame>1
                </use_parent_model_frame>
            </axis>
        </joint>
        <link name="rotor_5">
            <inertial>
                <mass>0.005
                </mass>
                <inertia>
                    <ixx>9.75e-07                    </ixx>
                    <ixy>0                    </ixy>
                    <ixz>0                    </ixz>
                    <iyy>8.13545e-05                    </iyy>
                    <iyz>0                    </iyz>
                    <izz>8.22545e-05                    </izz>
                </inertia>
            </inertial>
            <collision name="rotor_5_collision">
                <geometry>
                    <cylinder>
                        <length>0.005
                        </length>
                        <radius>0.1397
                        </radius>
                    </cylinder>
                </geometry>
                <surface>
                    <contact>
                        <ode/>
                    </contact>
                    <friction>
                        <ode/>
                    </friction>
                </surface>
            </collision>
            <visual name="rotor_5_visual">
                <geometry>
                    <mesh>
                        <scale>1 1 1
                        </scale>
                        <uri>model:://X4_GPS_LIDAR_RGBD/meshes/neo11_propeller_cw.dae
                        </uri>
                    </mesh>
                </geometry>
                <cast_shadows>0
                </cast_shadows>
            </visual>
            <gravity>1
            </gravity>
            <velocity_decay/>
        </link>
        <joint name="rotor_5_joint" type="revolute">
            <child>rotor_5
            </child>
            <parent>base_link
            </parent>
            <axis>
                <xyz>0.043578 0.075479 0.996195
                </xyz>
                <limit>
                    <lower>-1e+16
                    </lower>
                    <upper>1e+16
                    </upper>
                </limit>
                <dynamics>
                    <spring_reference>0
                    </spring_reference>
                    <spring_stiffness>0
                    </spring_stiffness>
                </dynamics>
                <use_parent_model_frame>1
                </use_parent_model_frame>
            </axis>
        </joint>
        
        <!-- now some plugins -->
        <plugin filename="ignition-gazebo-multicopter-motor-model-system" name="ignition::gazebo::systems::MulticopterMotorModel">
            <robotNamespace>X4
            </robotNamespace>
            <jointName>rotor_0_joint
            </jointName>
            <linkName>rotor_0
            </linkName>
            <turningDirection>ccw
            </turningDirection>
            <timeConstantUp>0.0182
            </timeConstantUp>
            <timeConstantDown>0.0182
            </timeConstantDown>
            <maxRotVelocity>1000.0
            </maxRotVelocity>
            <motorConstant>1.269e-05
            </motorConstant>
            <momentConstant>0.016754
            </momentConstant>
            <commandSubTopic>command/motor_speed
            </commandSubTopic>
            <motorNumber>0
            </motorNumber>
            <rotorDragCoefficient>2.0673e-04
            </rotorDragCoefficient>
            <rotorDragCoefficient>0
            </rotorDragCoefficient>
            <rollingMomentCoefficient>0
            </rollingMomentCoefficient>
            <motorSpeedPubTopic>motor_speed/0
            </motorSpeedPubTopic>
            <rotorVelocitySlowdownSim>2
            </rotorVelocitySlowdownSim>
            <motorType>velocity
            </motorType>
        </plugin>
        <plugin filename="ignition-gazebo-multicopter-motor-model-system"  name="ignition::gazebo::systems::MulticopterMotorModel">
            <robotNamespace>X4
            </robotNamespace>
            <jointName>rotor_1_joint
            </jointName>
            <linkName>rotor_1
            </linkName>
            <turningDirection>cw
            </turningDirection>
            <timeConstantUp>0.0182
            </timeConstantUp>
            <timeConstantDown>0.0182
            </timeConstantDown>
            <maxRotVelocity>1000.0
            </maxRotVelocity>
            <motorConstant>1.269e-05
            </motorConstant>
            <momentConstant>0.016754
            </momentConstant>
            <commandSubTopic>command/motor_speed
            </commandSubTopic>
            <motorNumber>1
            </motorNumber>
            <rotorDragCoefficient>2.0673e-04
            </rotorDragCoefficient>
            <rotorDragCoefficient>0
            </rotorDragCoefficient>
            <rollingMomentCoefficient>0
            </rollingMomentCoefficient>
            <motorSpeedPubTopic>motor_speed/1
            </motorSpeedPubTopic>
            <rotorVelocitySlowdownSim>2
            </rotorVelocitySlowdownSim>
            <motorType>velocity
            </motorType>
        </plugin>
        <plugin filename="ignition-gazebo-multicopter-motor-model-system"
  name="ignition::gazebo::systems::MulticopterMotorModel">
            <robotNamespace>X4
            </robotNamespace>
            <jointName>rotor_2_joint
            </jointName>
            <linkName>rotor_2
            </linkName>
            <turningDirection>ccw
            </turningDirection>
            <timeConstantUp>0.0182
            </timeConstantUp>
            <timeConstantDown>0.0182
            </timeConstantDown>
            <maxRotVelocity>1000.0
            </maxRotVelocity>
            <motorConstant>1.269e-05
            </motorConstant>
            <momentConstant>0.016754
            </momentConstant>
            <commandSubTopic>command/motor_speed
            </commandSubTopic>
            <motorNumber>2
            </motorNumber>
            <rotorDragCoefficient>2.0673e-04
            </rotorDragCoefficient>
            <rotorDragCoefficient>0
            </rotorDragCoefficient>
            <rollingMomentCoefficient>0
            </rollingMomentCoefficient>
            <motorSpeedPubTopic>motor_speed/2
            </motorSpeedPubTopic>
            <rotorVelocitySlowdownSim>2
            </rotorVelocitySlowdownSim>
            <motorType>velocity
            </motorType>
        </plugin>
        <plugin filename="ignition-gazebo-multicopter-motor-model-system"
  name="ignition::gazebo::systems::MulticopterMotorModel">
            <robotNamespace>X4
            </robotNamespace>
            <jointName>rotor_3_joint
            </jointName>
            <linkName>rotor_3
            </linkName>
            <turningDirection>cw
            </turningDirection>
            <timeConstantUp>0.0182
            </timeConstantUp>
            <timeConstantDown>0.0182
            </timeConstantDown>
            <maxRotVelocity>1000.0
            </maxRotVelocity>
            <motorConstant>1.269e-05
            </motorConstant>
            <momentConstant>0.016754
            </momentConstant>
            <commandSubTopic>command/motor_speed
            </commandSubTopic>
            <motorNumber>3
            </motorNumber>
            <rotorDragCoefficient>2.0673e-04
            </rotorDragCoefficient>
            <rotorDragCoefficient>0
            </rotorDragCoefficient>
            <rollingMomentCoefficient>0
            </rollingMomentCoefficient>
            <motorSpeedPubTopic>motor_speed/3
            </motorSpeedPubTopic>
            <rotorVelocitySlowdownSim>2
            </rotorVelocitySlowdownSim>
            <motorType>velocity
            </motorType>
        </plugin>
        <plugin filename="ignition-gazebo-multicopter-motor-model-system"
  name="ignition::gazebo::systems::MulticopterMotorModel">
            <robotNamespace>X4
            </robotNamespace>
            <jointName>rotor_4_joint
            </jointName>
            <linkName>rotor_4
            </linkName>
            <turningDirection>ccw
            </turningDirection>
            <timeConstantUp>0.0182
            </timeConstantUp>
            <timeConstantDown>0.0182
            </timeConstantDown>
            <maxRotVelocity>1000.0
            </maxRotVelocity>
            <motorConstant>1.269e-05
            </motorConstant>
            <momentConstant>0.016754
            </momentConstant>
            <commandSubTopic>command/motor_speed
            </commandSubTopic>
            <motorNumber>4
            </motorNumber>
            <rotorDragCoefficient>2.0673e-04
            </rotorDragCoefficient>
            <rotorDragCoefficient>0
            </rotorDragCoefficient>
            <rollingMomentCoefficient>0
            </rollingMomentCoefficient>
            <motorSpeedPubTopic>motor_speed/4
            </motorSpeedPubTopic>
            <rotorVelocitySlowdownSim>2
            </rotorVelocitySlowdownSim>
            <motorType>velocity
            </motorType>
        </plugin>
        <plugin filename="ignition-gazebo-multicopter-motor-model-system"
  name="ignition::gazebo::systems::MulticopterMotorModel">
            <robotNamespace>X4
            </robotNamespace>
            <jointName>rotor_5_joint
            </jointName>
            <linkName>rotor_5
            </linkName>
            <turningDirection>cw
            </turningDirection>
            <timeConstantUp>0.0182
            </timeConstantUp>
            <timeConstantDown>0.0182
            </timeConstantDown>
            <maxRotVelocity>1000.0
            </maxRotVelocity>
            <motorConstant>1.269e-05
            </motorConstant>
            <momentConstant>0.016754
            </momentConstant>
            <commandSubTopic>command/motor_speed
            </commandSubTopic>
            <motorNumber>5
            </motorNumber>
            <rotorDragCoefficient>2.0673e-04
            </rotorDragCoefficient>
            <rotorDragCoefficient>0
            </rotorDragCoefficient>
            <rollingMomentCoefficient>0
            </rollingMomentCoefficient>
            <motorSpeedPubTopic>motor_speed/5
            </motorSpeedPubTopic>
            <rotorVelocitySlowdownSim>2
            </rotorVelocitySlowdownSim>
            <motorType>velocity
            </motorType>
        </plugin>
        
        <plugin   filename="ignition-gazebo-multicopter-control-system"   name="ignition::gazebo::systems::MulticopterVelocityControl">
            <robotNamespace>X4
            </robotNamespace>
            <commandSubTopic>cmd_vel
            </commandSubTopic>
            <enableSubTopic>enable
            </enableSubTopic>
            <comLinkName>base_link
            </comLinkName>
            <velocityGain>6 6 10
            </velocityGain>
            <attitudeGain>4 4 2
            </attitudeGain>
            <angularRateGain>0.7 0.7 0.7
            </angularRateGain>
            <maximumLinearAcceleration>1 1 2
            </maximumLinearAcceleration>
            <maximumLinearVelocity>5 5 5
            </maximumLinearVelocity>
            <maximumAngularVelocity>3 3 3
            </maximumAngularVelocity>
            <linearVelocityNoiseMean>0 0 0
            </linearVelocityNoiseMean>
            <!-- linearVelocityNoiseStdDev based on error values reported in the paper Shen et. al., -->
            <!-- Vision-Based State Estimation and Trajectory Control Towards High-Speed Flight with a Quadrotor -->
            <!-- http://citeseerx.ist.psu.edu/viewdoc/download?doi=10.1.1.490.7958&rep=rep1&type=pdf -->
        </plugin>
    </model>
</sdf>